test_0 (__main__.lab2a.test_0)
[Lab 2] - [Investigation 1] - [Part 1] - variables & printing - Test for file creation: ./lab2a.py ... ok
test_1 (__main__.lab2a.test_1)
[Lab 2] - [Investigation 1] - [Part 1] - variables & printing - Test for errors running: ./lab2a.py ... /usr/lib/python3.12/subprocess.py:822: ResourceWarning: unclosed file <_io.TextIOWrapper name=3 encoding='UTF-8'>
  _cleanup()
ResourceWarning: Enable tracemalloc to get the object allocation traceback
ok
test_2 (__main__.lab2a.test_2)
[Lab 2] - [Investigation 1] - [Part 1] - variables & printing - Test for correct shebang line: ./lab2a.py ... ok
test_3 (__main__.lab2a.test_3)
[Lab 2] - [Investigation 1] - [Part 1] - variables & printing - Test for correct output: ./lab2a.py ... ok
test_0 (__main__.lab2b.test_0)
[Lab 2] - [Investigation 1] - [Part 1] - using input() function - Test for file creation: ./lab2b.py ... ok
test_1 (__main__.lab2b.test_1)
[Lab 2] - [Investigation 1] - [Part 1] - using input() - Test for errors with sending input "Jon" "20": ./lab2b.py ... ok
test_2 (__main__.lab2b.test_2)
[Lab 2] - [Investigation 1] - [Part 1] - using input() - Test for correct shebang line: ./lab2b.py ... ok
test_3 (__main__.lab2b.test_3)
[Lab 2] - [Investigation 1] - [Part 1] - using input() - Test output with sending input "Jon" "20": ./lab2b.py ... ok
test_4 (__main__.lab2b.test_4)
[Lab 2] - [Investigation 1] - [Part 1] - using input() - Test output with sending input "Jen" "25": ./lab2b.py ... ok
test_0 (__main__.lab2c.test_0)
[Lab 2] - [Investigation 1] - [Part 2] - command line arguments - Test for file creation: ./lab2c.py ... ok
test_1 (__main__.lab2c.test_1)
[Lab 2] - [Investigation 1] - [Part 2] - command line arguments - Test for errors with 2 args: ./lab2c.py Jon 20 ... ok
test_2 (__main__.lab2c.test_2)
[Lab 2] - [Investigation 1] - [Part 2] - command line arguments - Test for correct shebang line: ./lab2c.py ... ok
test_3 (__main__.lab2c.test_3)
[Lab 2] - [Investigation 1] - [Part 2] - command line arguments - Test output for: ./lab2c.py Jon 20 ... FAIL

======================================================================
FAIL: test_3 (__main__.lab2c.test_3)
[Lab 2] - [Investigation 1] - [Part 2] - command line arguments - Test output for: ./lab2c.py Jon 20
----------------------------------------------------------------------
Traceback (most recent call last):
  File "/home/sean/ops445/lab-2-SeanD66/./CheckLab2.py", line 157, in test_3
    self.assertEqual(stdout, expected_output, msg=error_output)
AssertionError: b'3\nyou do not have 10 arguments\n' != b'Hi Jon, you are 20 years old.\n' : output is not correct (HINT: must use the sys.argv list, do not forget to import sys)

----------------------------------------------------------------------
Ran 13 tests in 0.077s

FAILED (failures=1)
OPS445 Lab Report - System Information for running ./CheckLab2.py
=================================================================
    User login name: sean
    Git Email: sdaweng@myseneca.ca
    Linux system name: sean-VirtualBox
    Python executable: /usr/bin/python3
    Python version:  3.12.3 (main, Feb  4 2025, 14:48:35) [GCC 13.3.0]
    OS Platform: linux
    Working Directory: /home/sean/ops445/lab-2-SeanD66
    Start at: Tue May 13 20:48:46 2025
=================================================================
